Workbook

Sheet Assumptions
A1: VetFinance | 5-Year Financial Forecast | Assumptions
A3: PRACTICE GROWTH
A4: Model start date | B4: 46569 | C4: First month of operations
A5: Practices active at launch (Month 1) | B5: 1 | C5: Founding / pilot clinics
A6: New practices signed per month — Year 1 | B6: 6 | C6: Early-adopter ramp
A7: New practices signed per month — Year 2 | B7: 18
A8: New practices signed per month — Year 3 | B8: 25
A9: New practices signed per month — Year 4 | B9: 20 | C9: Growth moderating
A10: New practices signed per month — Year 5 | B10: 12 | C10: Market maturing
A11: Monthly churn rate (% of active practices) | B11: 0.005 | C11: ~6% annually; practices leaving
A13: LOAN ECONOMICS
A14: Referrals per practice per week | B14: 2 | C14: Pet-owner referrals sent to financing
A15: Application approval rate | B15: 0.65 | C15: % of referrals approved & funded
A16: Average loan size ($) | B16: 1800 | C16: Avg financed amount per approved loan
A17: Average repayment period (months) | B17: 14 | C17: Avg expected loan duration
A18: Annual interest rate charged to borrower (APR) | B18: 0.19 | C18: CareCredit charges 26.99% standard
A19: Origination / processing fee (% of loan) | B19: 0.02 | C19: Collected upfront at funding
A20: Annual net loss rate (% of avg portfolio) | B20: 0.06 | C20: Charge-offs net of recoveries
A22: FUNDING & CAPITAL STRUCTURE
A23: Annual cost of debt (warehouse / credit facility) | B23: 0.09 | C23: Interest on borrowed capital
A24: Max leverage — debt ÷ equity on loan portfolio | B24: 7 | C24: 3x = 75% debt / 25% equity funded
A25: Minimum cash buffer (months of operating expenses) | B25: 6 | C25: Liquidity reserve on top of portfolio funding
A27: OPERATING EXPENSES (Year 1 Annualised)
A28: Salaries & Benefits (4 FTEs) | B28: =(75000+65000)*1.2 | C28: 2 founders @$60k, 1 underwriter @$75k, 1 ops @$65k (+20% taxes/benefits)
A29: Technology & Platform | B29: 63000 | C29: AWS $30k | Plaid $0.50/app ~$4k | Experian $1.50/app ~$12k | LOS/SaaS $12k | misc $5k
A30: Sales & Marketing | B30: 100000 | C30: Practice acquisition, collateral
A31: Compliance & Legal | B31: 150000 | C31: Licensing, counsel, audits
A32: G&A / Office | B32: 25000 | C32: Remote-first; virtual office, insurance, accounting — minimal footprint
A33: Total Year 1 Annual Opex | B33: =SUM(B28:B32)
A34: Annual opex growth rate (Year 2 onward) | B34: 0.5 | C34: Headcount & infrastructure scaling
A35: STARTING CAPITAL
A36: Initial equity raised before launch ($) | B36: 1000000
A38: COLOUR LEGEND
A39: ● Blue = Hardcoded input — change these to model scenarios
A40: ● Black = Formula — do not edit
A41: ● Green = Cross-sheet link — do not edit
A43: WAREHOUSE FACILITY & CASH MANAGEMENT
A44: Warehouse facility committed limit ($) | B44: 10000000 | C44: Committed size of the revolving warehouse credit line
A45: (Legacy — superseded by the loan-count facility gate below; not used in formulas) | B45: 1
A46: Yield earned on excess cash above buffer (annualized) | B46: 0.045 | C46: Idle cash above the minimum buffer is swept into short-term investments (T-bills / money market)
...

Sheet Monthly Model
A1: PERIOD | D1: PRACTICE GROWTH | G1: LOAN VOLUME | J1: LOAN PORTFOLIO | O1: REVENUE | R1: COSTS & NET OP INCOME | U1: FUNDING | Y1: CAPITAL REQUIREMENTS | AE1: WAREHOUSE FACILITY, CASH SWEEP & RAISE TRIGGER | AO1: BANK PARTNERSHIP (WEBBANK)
A2: Mo# | B2: Date | C2: Yr | D2: New Practices | E2: Churned Practices | F2: Active Practices | G2: Monthly Referrals | H2: Approved Loans | I2: Originations — Your Share ($) | J2: Beg Portfolio ($) | K2: Repayments ($) | L2: Charge-offs ($) | M2: End Portfolio ($) | N2: Avg Portfolio ($) | O2: Interest Income ($) | P2: Orig Fees ($) | Q2: Total Revenue ($) | R2: Opex ($) | S2: Provision ($) | T2: Net Op Income ($) | U2: End Debt Balance ($) | V2: Interest Expense ($) | W2: Net Income ($) | X2: Cum Net Income ($) | Y2: Portfolio Equity ($) | Z2: Cash Buffer ($) | AA2: Total Equity Required ($) | AB2: Peak Equity Required ($) | AC2: Raise Triggered ($) | AD2: End Cash & Investments ($) | AE2: Facility Limit ($) | AF2: Debt Draw / (Repay) ($) | AG2: Facility Utilization (%) | AH2: Facility Increase This Month ($) | AI2: Investable Excess Cash ($) | AJ2: Investment Income ($) | AK2: Cash Before Raise ($) | AL2: Recommended Action | AM2: Net CF ex-Raise, ex-Invest Inc ($) | AN2: Cumulative Loans Funded | AO2: Gross Program Originations ($) | AP2: Bank Partnership Costs ($) | AQ2: Est. Bank's Retained Interest & Fees ($)
A3: 0 | C3: 0 | U3: 0 | AD3: =Assumptions!B36 | AE3: =Assumptions!$B$44
A4: 1 | B4: =EDATE(Assumptions!$B$4,0) | C4: =INT((A4-1)/12)+1 | D4: =IF(C4=1,Assumptions!$B$6,IF(C4=2,Assumptions!$B$7,IF(C4=3,Assumptions!$B$8,IF(C4=4,Assumptions!$B$9,Assumptions!$B$10)))) | E4: 0 | F4: =Assumptions!B5 | G4: =ROUND(F4*Assumptions!$B$14*(365/12/7),0) | H4: =ROUND(G4*Assumptions!$B$15,0) | I4: =AO4*(1-Assumptions!$B$61) | J4: 0 | K4: =IFERROR(J4/Assumptions!$B$17,0) | L4: =J4*Assumptions!$B$20/12 | M4: =MAX(J4+I4-K4-L4,0) | N4: =(J4+M4)/2 | O4: =N4*Assumptions!$B$18/12 | P4: =I4*Assumptions!$B$19 | Q4: =O4+P4 | R4: =Assumptions!$B$33*(1+Assumptions!$B$34)^(C4-1)/12 | S4: =L4 | T4: =Q4-R4-S4-AP4 | U4: =MIN(AE4,M4*Assumptions!$B$24/(1+Assumptions!$B$24)) | V4: =((U4+U3)/2)*Assumptions!$B$23/12 | W4: =T4-V4+AJ4 | X4: =W4 | Y4: =MAX(M4-U4,0) | Z4: =R4*Assumptions!$B$25 | AA4: =Y4+Z4 | AB4: =AA4 | AC4: =MAX(0,MAX(Z4-AD3-AM4,Z5-AD3-SUM(AM4:AM5),Z6-AD3-SUM(AM4:AM6),Z7-AD3-SUM(AM4:AM7),Z8-AD3-SUM(AM4:AM8),Z9-AD3-SUM(AM4:AM9),Z10-AD3-SUM(AM4:AM10),Z11-AD3-SUM(AM4:AM11),Z12-AD3-SUM(AM4:AM12),Z13-AD3-SUM(AM4:AM13),Z14-AD3-SUM(AM4:AM14),Z15-AD3-SUM(AM4:AM15))) | AD4: =AK4+AC4 | AE4: =IF(SUM($H$4:H4)<Assumptions!$B$57,0,MAX(MAX(Assumptions!$B$44,AE3),IF(M4*Assumptions!$B$24/(1+Assumptions!$B$24)>MAX(Assumptions!$B$44,AE3)*Assumptions!$B$53,M4*Assumptions!$B$24/(1+Assumptions!$B$24)/Assumptions!$B$54,MAX(Assumptions!$B$44,AE3)))) | AF4: =U4-U3 | AG4: =IFERROR(U4/AE4,0) | AH4: =MAX(0,AE4-AE3) | AI4: =MAX(AD3-Z4,0) | AJ4: =AI4*Assumptions!$B$46/12 | AK4: =AD3+Q4-R4-I4+K4+AF4-V4+AJ4-AP4 | AL4: =TRIM(IF(AH4>0,"Increase warehouse facility to $"&TEXT(AE4,"#,##0")&" (from $"&TEXT(AE3,"#,##0")&"). ","")&IF(AC4>0,"Raise ~$"&TEXT(AC4,"#,##0")&" of equity — annual raise, funds the next 12 months.","")) | AM4: =Q4-R4-I4+K4+AF4-V4-AP4 | AN4: =SUM($H$4:H4) | AO4: =H4*Assumptions!$B$16 | AP4: =MAX(AO4*Assumptions!$B$62,Assumptions!$B$63)+Assumptions!$B$64/12 | AQ4: =(O4+P4)*Assumptions!$B$61/(1-Assumptions!$B$61)
A5: 2 | B5: =EDATE(Assumptions!$B$4,1) | C5: =INT((A5-1)/12)+1 | D5: =IF(C5=1,Assumptions!$B$6,IF(C5=2,Assumptions!$B$7,IF(C5=3,Assumptions!$B$8,IF(C5=4,Assumptions!$B$9,Assumptions!$B$10)))) | E5: =ROUND(F4*Assumptions!$B$11,0) | F5: =F4+1 | G5: =ROUND(F5*Assumptions!$B$14*(365/12/7),0) | H5: =ROUND(G5*Assumptions!$B$15,0) | I5: =AO5*(1-Assumptions!$B$61) | J5: =M4 | K5: =IFERROR(J5/Assumptions!$B$17,0) | L5: =J5*Assumptions!$B$20/12 | M5: =MAX(J5+I5-K5-L5,0) | N5: =(J5+M5)/2 | O5: =N5*Assumptions!$B$18/12 | P5: =I5*Assumptions!$B$19 | Q5: =O5+P5 | R5: =Assumptions!$B$33*(1+Assumptions!$B$34)^(C5-1)/12 | S5: =L5 | T5: =Q5-R5-S5-AP5 | U5: =MIN(AE5,M5*Assumptions!$B$24/(1+Assumptions!$B$24)) | V5: =((U5+U4)/2)*Assumptions!$B$23/12 | W5: =T5-V5+AJ5 | X5: =X4+W5 | Y5: =MAX(M5-U5,0) | Z5: =R5*Assumptions!$B$25 | AA5: =Y5+Z5 | AB5: =MAX(AB4,AA5) | AC5: 0 | AD5: =AK5+AC5 | AE5: =IF(SUM($H$4:H5)<Assumptions!$B$57,0,MAX(MAX(Assumptions!$B$44,AE4),IF(M5*Assumptions!$B$24/(1+Assumptions!$B$24)>MAX(Assumptions!$B$44,AE4)*Assumptions!$B$53,M5*Assumptions!$B$24/(1+Assumptions!$B$24)/Assumptions!$B$54,MAX(Assumptions!$B$44,AE4)))) | AF5: =U5-U4 | AG5: =IFERROR(U5/AE5,0) | AH5: =MAX(0,AE5-AE4) | AI5: =MAX(AD4-Z5,0) | AJ5: =AI5*Assumptions!$B$46/12 | AK5: =AD4+Q5-R5-I5+K5+AF5-V5+AJ5-AP5 | AL5: =TRIM(IF(AH5>0,"Increase warehouse facility to $"&TEXT(AE5,"#,##0")&" (from $"&TEXT(AE4,"#,##0")&"). ","")&IF(AC5>0,"Raise ~$"&TEXT(AC5,"#,##0")&" of equity — annual raise, funds the next 12 months.","")) | AM5: =Q5-R5-I5+K5+AF5-V5-AP5 | AN5: =SUM($H$4:H5) | AO5: =H5*Assumptions!$B$16 | AP5: =MAX(AO5*Assumptions!$B$62,Assumptions!$B$63)+Assumptions!$B$64/12 | AQ5: =(O5+P5)*Assumptions!$B$61/(1-Assumptions!$B$61)
A6: 3 | B6: =EDATE(Assumptions!$B$4,2) | C6: =INT((A6-1)/12)+1 | D6: =IF(C6=1,Assumptions!$B$6,IF(C6=2,Assumptions!$B$7,IF(C6=3,Assumptions!$B$8,IF(C6=4,Assumptions!$B$9,Assumptions!$B$10)))) | E6: =ROUND(F5*Assumptions!$B$11,0) | F6: =F5+1 | G6: =ROUND(F6*Assumptions!$B$14*(365/12/7),0) | H6: =ROUND(G6*Assumptions!$B$15,0) | I6: =AO6*(1-Assumptions!$B$61) | J6: =M5 | K6: =IFERROR(J6/Assumptions!$B$17,0) | L6: =J6*Assumptions!$B$20/12 | M6: =MAX(J6+I6-K6-L6,0) | N6: =(J6+M6)/2 | O6: =N6*Assumptions!$B$18/12 | P6: =I6*Assumptions!$B$19 | Q6: =O6+P6 | R6: =Assumptions!$B$33*(1+Assumptions!$B$34)^(C6-1)/12 | S6: =L6 | T6: =Q6-R6-S6-AP6 | U6: =MIN(AE6,M6*Assumptions!$B$24/(1+Assumptions!$B$24)) | V6: =((U6+U5)/2)*Assumptions!$B$23/12 | W6: =T6-V6+AJ6 | X6: =X5+W6 | Y6: =MAX(M6-U6,0) | Z6: =R6*Assumptions!$B$25 | AA6: =Y6+Z6 | AB6: =MAX(AB5,AA6) | AC6: 0 | AD6: =AK6+AC6 | AE6: =IF(SUM($H$4:H6)<Assumptions!$B$57,0,MAX(MAX(Assumptions!$B$44,AE5),IF(M6*Assumptions!$B$24/(1+Assumptions!$B$24)>MAX(Assumptions!$B$44,AE5)*Assumptions!$B$53,M6*Assumptions!$B$24/(1+Assumptions!$B$24)/Assumptions!$B$54,MAX(Assumptions!$B$44,AE5)))) | AF6: =U6-U5 | AG6: =IFERROR(U6/AE6,0) | AH6: =MAX(0,AE6-AE5) | AI6: =MAX(AD5-Z6,0) | AJ6: =AI6*Assumptions!$B$46/12 | AK6: =AD5+Q6-R6-I6+K6+AF6-V6+AJ6-AP6 | AL6: =TRIM(IF(AH6>0,"Increase warehouse facility to $"&TEXT(AE6,"#,##0")&" (from $"&TEXT(AE5,"#,##0")&"). ","")&IF(AC6>0,"Raise ~$"&TEXT(AC6,"#,##0")&" of equity — annual raise, funds the next 12 months.","")) | AM6: =Q6-R6-I6+K6+AF6-V6-AP6 | AN6: =SUM($H$4:H6) | AO6: =H6*Assumptions!$B$16 | AP6: =MAX(AO6*Assumptions!$B$62,Assumptions!$B$63)+Assumptions!$B$64/12 | AQ6: =(O6+P6)*Assumptions!$B$61/(1-Assumptions!$B$61)
A7: 4 | B7: =EDATE(Assumptions!$B$4,3) | C7: =INT((A7-1)/12)+1 | D7: =IF(C7=1,Assumptions!$B$6,IF(C7=2,Assumptions!$B$7,IF(C7=3,Assumptions!$B$8,IF(C7=4,Assumptions!$B$9,Assumptions!$B$10)))) | E7: =ROUND(F6*Assumptions!$B$11,0) | F7: =F6+1 | G7: =ROUND(F7*Assumptions!$B$14*(365/12/7),0) | H7: =ROUND(G7*Assumptions!$B$15,0) | I7: =AO7*(1-Assumptions!$B$61) | J7: =M6 | K7: =IFERROR(J7/Assumptions!$B$17,0) | L7: =J7*Assumptions!$B$20/12 | M7: =MAX(J7+I7-K7-L7,0) | N7: =(J7+M7)/2 | O7: =N7*Assumptions!$B$18/12 | P7: =I7*Assumptions!$B$19 | Q7: =O7+P7 | R7: =Assumptions!$B$33*(1+Assumptions!$B$34)^(C7-1)/12 | S7: =L7 | T7: =Q7-R7-S7-AP7 | U7: =MIN(AE7,M7*Assumptions!$B$24/(1+Assumptions!$B$24)) | V7: =((U7+U6)/2)*Assumptions!$B$23/12 | W7: =T7-V7+AJ7 | X7: =X6+W7 | Y7: =MAX(M7-U7,0) | Z7: =R7*Assumptions!$B$25 | AA7: =Y7+Z7 | AB7: =MAX(AB6,AA7) | AC7: 0 | AD7: =AK7+AC7 | AE7: =IF(SUM($H$4:H7)<Assumptions!$B$57,0,MAX(MAX(Assumptions!$B$44,AE6),IF(M7*Assumptions!$B$24/(1+Assumptions!$B$24)>MAX(Assumptions!$B$44,AE6)*Assumptions!$B$53,M7*Assumptions!$B$24/(1+Assumptions!$B$24)/Assumptions!$B$54,MAX(Assumptions!$B$44,AE6)))) | AF7: =U7-U6 | AG7: =IFERROR(U7/AE7,0) | AH7: =MAX(0,AE7-AE6) | AI7: =MAX(AD6-Z7,0) | AJ7: =AI7*Assumptions!$B$46/12 | AK7: =AD6+Q7-R7-I7+K7+AF7-V7+AJ7-AP7 | AL7: =TRIM(IF(AH7>0,"Increase warehouse facility to $"&TEXT(AE7,"#,##0")&" (from $"&TEXT(AE6,"#,##0")&"). ","")&IF(AC7>0,"Raise ~$"&TEXT(AC7,"#,##0")&" of equity — annual raise, funds the next 12 months.","")) | AM7: =Q7-R7-I7+K7+AF7-V7-AP7 | AN7: =SUM($H$4:H7) | AO7: =H7*Assumptions!$B$16 | AP7: =MAX(AO7*Assumptions!$B$62,Assumptions!$B$63)+Assumptions!$B$64/12 | AQ7: =(O7+P7)*Assumptions!$B$61/(1-Assumptions!$B$61)
A8: 5 | B8: =EDATE(Assumptions!$B$4,4) | C8: =INT((A8-1)/12)+1 | D8: =IF(C8=1,Assumptions!$B$6,IF(C8=2,Assumptions!$B$7,IF(C8=3,Assumptions!$B$8,IF(C8=4,Assumptions!$B$9,Assumptions!$B$10)))) | E8: =ROUND(F7*Assumptions!$B$11,0) | F8: =F7+1 | G8: =ROUND(F8*Assumptions!$B$14*(365/12/7),0) | H8: =ROUND(G8*Assumptions!$B$15,0) | I8: =AO8*(1-Assumptions!$B$61) | J8: =M7 | K8: =IFERROR(J8/Assumptions!$B$17,0) | L8: =J8*Assumptions!$B$20/12 | M8: =MAX(J8+I8-K8-L8,0) | N8: =(J8+M8)/2 | O8: =N8*Assumptions!$B$18/12 | P8: =I8*Assumptions!$B$19 | Q8: =O8+P8 | R8: =Assumptions!$B$33*(1+Assumptions!$B$34)^(C8-1)/12 | S8: =L8 | T8: =Q8-R8-S8-AP8 | U8: =MIN(AE8,M8*Assumptions!$B$24/(1+Assumptions!$B$24)) | V8: =((U8+U7)/2)*Assumptions!$B$23/12 | W8: =T8-V8+AJ8 | X8: =X7+W8 | Y8: =MAX(M8-U8,0) | Z8: =R8*Assumptions!$B$25 | AA8: =Y8+Z8 | AB8: =MAX(AB7,AA8) | AC8: 0 | AD8: =AK8+AC8 | AE8: =IF(SUM($H$4:H8)<Assumptions!$B$57,0,MAX(MAX(Assumptions!$B$44,AE7),IF(M8*Assumptions!$B$24/(1+Assumptions!$B$24)>MAX(Assumptions!$B$44,AE7)*Assumptions!$B$53,M8*Assumptions!$B$24/(1+Assumptions!$B$24)/Assumptions!$B$54,MAX(Assumptions!$B$44,AE7)))) | AF8: =U8-U7 | AG8: =IFERROR(U8/AE8,0) | AH8: =MAX(0,AE8-AE7) | AI8: =MAX(AD7-Z8,0) | AJ8: =AI8*Assumptions!$B$46/12 | AK8: =AD7+Q8-R8-I8+K8+AF8-V8+AJ8-AP8 | AL8: =TRIM(IF(AH8>0,"Increase warehouse facility to $"&TEXT(AE8,"#,##0")&" (from $"&TEXT(AE7,"#,##0")&"). ","")&IF(AC8>0,"Raise ~$"&TEXT(AC8,"#,##0")&" of equity — annual raise, funds the next 12 months.","")) | AM8: =Q8-R8-I8+K8+AF8-V8-AP8 | AN8: =SUM($H$4:H8) | AO8: =H8*Assumptions!$B$16 | AP8: =MAX(AO8*Assumptions!$B$62,Assumptions!$B$63)+Assumptions!$B$64/12 | AQ8: =(O8+P8)*Assumptions!$B$61/(1-Assumptions!$B$61)
A9: 6 | B9: =EDATE(Assumptions!$B$4,5) | C9: =INT((A9-1)/12)+1 | D9: =IF(C9=1,Assumptions!$B$6,IF(C9=2,Assumptions!$B$7,IF(C9=3,Assumptions!$B$8,IF(C9=4,Assumptions!$B$9,Assumptions!$B$10)))) | E9: =ROUND(F8*Assumptions!$B$11,0) | F9: =F8+1 | G9: =ROUND(F9*Assumptions!$B$14*(365/12/7),0) | H9: =ROUND(G9*Assumptions!$B$15,0) | I9: =AO9*(1-Assumptions!$B$61) | J9: =M8 | K9: =IFERROR(J9/Assumptions!$B$17,0) | L9: =J9*Assumptions!$B$20/12 | M9: =MAX(J9+I9-K9-L9,0) | N9: =(J9+M9)/2 | O9: =N9*Assumptions!$B$18/12 | P9: =I9*Assumptions!$B$19 | Q9: =O9+P9 | R9: =Assumptions!$B$33*(1+Assumptions!$B$34)^(C9-1)/12 | S9: =L9 | T9: =Q9-R9-S9-AP9 | U9: =MIN(AE9,M9*Assumptions!$B$24/(1+Assumptions!$B$24)) | V9: =((U9+U8)/2)*Assumptions!$B$23/12 | W9: =T9-V9+AJ9 | X9: =X8+W9 | Y9: =MAX(M9-U9,0) | Z9: =R9*Assumptions!$B$25 | AA9: =Y9+Z9 | AB9: =MAX(AB8,AA9) | AC9: 0 | AD9: =AK9+AC9 | AE9: =IF(SUM($H$4:H9)<Assumptions!$B$57,0,MAX(MAX(Assumptions!$B$44,AE8),IF(M9*Assumptions!$B$24/(1+Assumptions!$B$24)>MAX(Assumptions!$B$44,AE8)*Assumptions!$B$53,M9*Assumptions!$B$24/(1+Assumptions!$B$24)/Assumptions!$B$54,MAX(Assumptions!$B$44,AE8)))) | AF9: =U9-U8 | AG9: =IFERROR(U9/AE9,0) | AH9: =MAX(0,AE9-AE8) | AI9: =MAX(AD8-Z9,0) | AJ9: =AI9*Assumptions!$B$46/12 | AK9: =AD8+Q9-R9-I9+K9+AF9-V9+AJ9-AP9 | AL9: =TRIM(IF(AH9>0,"Increase warehouse facility to $"&TEXT(AE9,"#,##0")&" (from $"&TEXT(AE8,"#,##0")&"). ","")&IF(AC9>0,"Raise ~$"&TEXT(AC9,"#,##0")&" of equity — annual raise, funds the next 12 months.","")) | AM9: =Q9-R9-I9+K9+AF9-V9-AP9 | AN9: =SUM($H$4:H9) | AO9: =H9*Assumptions!$B$16 | AP9: =MAX(AO9*Assumptions!$B$62,Assumptions!$B$63)+Assumptions!$B$64/12 | AQ9: =(O9+P9)*Assumptions!$B$61/(1-Assumptions!$B$61)
A10: 7 | B10: =EDATE(Assumptions!$B$4,6) | C10: =INT((A10-1)/12)+1 | D10: =IF(C10=1,Assumptions!$B$6,IF(C10=2,Assumptions!$B$7,IF(C10=3,Assumptions!$B$8,IF(C10=4,Assumptions!$B$9,Assumptions!$B$10)))) | E10: =ROUND(F9*Assumptions!$B$11,0) | F10: =F9+D10-E10 | G10: =ROUND(F10*Assumptions!$B$14*(365/12/7),0) | H10: =ROUND(G10*Assumptions!$B$15,0) | I10: =AO10*(1-Assumptions!$B$61) | J10: =M9 | K10: =IFERROR(J10/Assumptions!$B$17,0) | L10: =J10*Assumptions!$B$20/12 | M10: =MAX(J10+I10-K10-L10,0) | N10: =(J10+M10)/2 | O10: =N10*Assumptions!$B$18/12 | P10: =I10*Assumptions!$B$19 | Q10: =O10+P10 | R10: =Assumptions!$B$33*(1+Assumptions!$B$34)^(C10-1)/12 | S10: =L10 | T10: =Q10-R10-S10-AP10 | U10: =MIN(AE10,M10*Assumptions!$B$24/(1+Assumptions!$B$24)) | V10: =((U10+U9)/2)*Assumptions!$B$23/12 | W10: =T10-V10+AJ10 | X10: =X9+W10 | Y10: =MAX(M10-U10,0) | Z10: =R10*Assumptions!$B$25 | AA10: =Y10+Z10 | AB10: =MAX(AB9,AA10) | AC10: 0 | AD10: =AK10+AC10 | AE10: =IF(SUM($H$4:H10)<Assumptions!$B$57,0,MAX(MAX(Assumptions!$B$44,AE9),IF(M10*Assumptions!$B$24/(1+Assumptions!$B$24)>MAX(Assumptions!$B$44,AE9)*Assumptions!$B$53,M10*Assumptions!$B$24/(1+Assumptions!$B$24)/Assumptions!$B$54,MAX(Assumptions!$B$44,AE9)))) | AF10: =U10-U9 | AG10: =IFERROR(U10/AE10,0) | AH10: =MAX(0,AE10-AE9) | AI10: =MAX(AD9-Z10,0) | AJ10: =AI10*Assumptions!$B$46/12 | AK10: =AD9+Q10-R10-I10+K10+AF10-V10+AJ10-AP10 | AL10: =TRIM(IF(AH10>0,"Increase warehouse facility to $"&TEXT(AE10,"#,##0")&" (from $"&TEXT(AE9,"#,##0")&"). ","")&IF(AC10>0,"Raise ~$"&TEXT(AC10,"#,##0")&" of equity — annual raise, funds the next 12 months.","")) | AM10: =Q10-R10-I10+K10+AF10-V10-AP10 | AN10: =SUM($H$4:H10) | AO10: =H10*Assumptions!$B$16 | AP10: =MAX(AO10*Assumptions!$B$62,Assumptions!$B$63)+Assumptions!$B$64/12 | AQ10: =(O10+P10)*Assumptions!$B$61/(1-Assumptions!$B$61)
A11: 8 | B11: =EDATE(Assumptions!$B$4,7) | C11: =INT((A11-1)/12)+1 | D11: =IF(C11=1,Assumptions!$B$6,IF(C11=2,Assumptions!$B$7,IF(C11=3,Assumptions!$B$8,IF(C11=4,Assumptions!$B$9,Assumptions!$B$10)))) | E11: =ROUND(F10*Assumptions!$B$11,0) | F11: =F10+D11-E11 | G11: =ROUND(F11*Assumptions!$B$14*(365/12/7),0) | H11: =ROUND(G11*Assumptions!$B$15,0) | I11: =AO11*(1-Assumptions!$B$61) | J11: =M10 | K11: =IFERROR(J11/Assumptions!$B$17,0) | L11: =J11*Assumptions!$B$20/12 | M11: =MAX(J11+I11-K11-L11,0) | N11: =(J11+M11)/2 | O11: =N11*Assumptions!$B$18/12 | P11: =I11*Assumptions!$B$19 | Q11: =O11+P11 | R11: =Assumptions!$B$33*(1+Assumptions!$B$34)^(C11-1)/12 | S11: =L11 | T11: =Q11-R11-S11-AP11 | U11: =MIN(AE11,M11*Assumptions!$B$24/(1+Assumptions!$B$24)) | V11: =((U11+U10)/2)*Assumptions!$B$23/12 | W11: =T11-V11+AJ11 | X11: =X10+W11 | Y11: =MAX(M11-U11,0) | Z11: =R11*Assumptions!$B$25 | AA11: =Y11+Z11 | AB11: =MAX(AB10,AA11) | AC11: 0 | AD11: =AK11+AC11 | AE11: =IF(SUM($H$4:H11)<Assumptions!$B$57,0,MAX(MAX(Assumptions!$B$44,AE10),IF(M11*Assumptions!$B$24/(1+Assumptions!$B$24)>MAX(Assumptions!$B$44,AE10)*Assumptions!$B$53,M11*Assumptions!$B$24/(1+Assumptions!$B$24)/Assumptions!$B$54,MAX(Assumptions!$B$44,AE10)))) | AF11: =U11-U10 | AG11: =IFERROR(U11/AE11,0) | AH11: =MAX(0,AE11-AE10) | AI11: =MAX(AD10-Z11,0) | AJ11: =AI11*Assumptions!$B$46/12 | AK11: =AD10+Q11-R11-I11+K11+AF11-V11+AJ11-AP11 | AL11: =TRIM(IF(AH11>0,"Increase warehouse facility to $"&TEXT(AE11,"#,##0")&" (from $"&TEXT(AE10,"#,##0")&"). ","")&IF(AC11>0,"Raise ~$"&TEXT(AC11,"#,##0")&" of equity — annual raise, funds the next 12 months.","")) | AM11: =Q11-R11-I11+K11+AF11-V11-AP11 | AN11: =SUM($H$4:H11) | AO11: =H11*Assumptions!$B$16 | AP11: =MAX(AO11*Assumptions!$B$62,Assumptions!$B$63)+Assumptions!$B$64/12 | AQ11: =(O11+P11)*Assumptions!$B$61/(1-Assumptions!$B$61)
A12: 9 | B12: =EDATE(Assumptions!$B$4,8) | C12: =INT((A12-1)/12)+1 | D12: =IF(C12=1,Assumptions!$B$6,IF(C12=2,Assumptions!$B$7,IF(C12=3,Assumptions!$B$8,IF(C12=4,Assumptions!$B$9,Assumptions!$B$10)))) | E12: =ROUND(F11*Assumptions!$B$11,0) | F12: =F11+D12-E12 | G12: =ROUND(F12*Assumptions!$B$14*(365/12/7),0) | H12: =ROUND(G12*Assumptions!$B$15,0) | I12: =AO12*(1-Assumptions!$B$61) | J12: =M11 | K12: =IFERROR(J12/Assumptions!$B$17,0) | L12: =J12*Assumptions!$B$20/12 | M12: =MAX(J12+I12-K12-L12,0) | N12: =(J12+M12)/2 | O12: =N12*Assumptions!$B$18/12 | P12: =I12*Assumptions!$B$19 | Q12: =O12+P12 | R12: =Assumptions!$B$33*(1+Assumptions!$B$34)^(C12-1)/12 | S12: =L12 | T12: =Q12-R12-S12-AP12 | U12: =MIN(AE12,M12*Assumptions!$B$24/(1+Assumptions!$B$24)) | V12: =((U12+U11)/2)*Assumptions!$B$23/12 | W12: =T12-V12+AJ12 | X12: =X11+W12 | Y12: =MAX(M12-U12,0) | Z12: =R12*Assumptions!$B$25 | AA12: =Y12+Z12 | AB12: =MAX(AB11,AA12) | AC12: 0 | AD12: =AK12+AC12 | AE12: =IF(SUM($H$4:H12)<Assumptions!$B$57,0,MAX(MAX(Assumptions!$B$44,AE11),IF(M12*Assumptions!$B$24/(1+Assumptions!$B$24)>MAX(Assumptions!$B$44,AE11)*Assumptions!$B$53,M12*Assumptions!$B$24/(1+Assumptions!$B$24)/Assumptions!$B$54,MAX(Assumptions!$B$44,AE11)))) | AF12: =U12-U11 | AG12: =IFERROR(U12/AE12,0) | AH12: =MAX(0,AE12-AE11) | AI12: =MAX(AD11-Z12,0) | AJ12: =AI12*Assumptions!$B$46/12 | AK12: =AD11+Q12-R12-I12+K12+AF12-V12+AJ12-AP12 | AL12: =TRIM(IF(AH12>0,"Increase warehouse facility to $"&TEXT(AE12,"#,##0")&" (from $"&TEXT(AE11,"#,##0")&"). ","")&IF(AC12>0,"Raise ~$"&TEXT(AC12,"#,##0")&" of equity — annual raise, funds the next 12 months.","")) | AM12: =Q12-R12-I12+K12+AF12-V12-AP12 | AN12: =SUM($H$4:H12) | AO12: =H12*Assumptions!$B$16 | AP12: =MAX(AO12*Assumptions!$B$62,Assumptions!$B$63)+Assumptions!$B$64/12 | AQ12: =(O12+P12)*Assumptions!$B$61/(1-Assumptions!$B$61)
A13: 10 | B13: =EDATE(Assumptions!$B$4,9) | C13: =INT((A13-1)/12)+1 | D13: =IF(C13=1,Assumptions!$B$6,IF(C13=2,Assumptions!$B$7,IF(C13=3,Assumptions!$B$8,IF(C13=4,Assumptions!$B$9,Assumptions!$B$10)))) | E13: =ROUND(F12*Assumptions!$B$11,0) | F13: =F12+D13-E13 | G13: =ROUND(F13*Assumptions!$B$14*(365/12/7),0) | H13: =ROUND(G13*Assumptions!$B$15,0) | I13: =AO13*(1-Assumptions!$B$61) | J13: =M12 | K13: =IFERROR(J13/Assumptions!$B$17,0) | L13: =J13*Assumptions!$B$20/12 | M13: =MAX(J13+I13-K13-L13,0) | N13: =(J13+M13)/2 | O13: =N13*Assumptions!$B$18/12 | P13: =I13*Assumptions!$B$19 | Q13: =O13+P13 | R13: =Assumptions!$B$33*(1+Assumptions!$B$34)^(C13-1)/12 | S13: =L13 | T13: =Q13-R13-S13-AP13 | U13: =MIN(AE13,M13*Assumptions!$B$24/(1+Assumptions!$B$24)) | V13: =((U13+U12)/2)*Assumptions!$B$23/12 | W13: =T13-V13+AJ13 | X13: =X12+W13 | Y13: =MAX(M13-U13,0) | Z13: =R13*Assumptions!$B$25 | AA13: =Y13+Z13 | AB13: =MAX(AB12,AA13) | AC13: 0 | AD13: =AK13+AC13 | AE13: =IF(SUM($H$4:H13)<Assumptions!$B$57,0,MAX(MAX(Assumptions!$B$44,AE12),IF(M13*Assumptions!$B$24/(1+Assumptions!$B$24)>MAX(Assumptions!$B$44,AE12)*Assumptions!$B$53,M13*Assumptions!$B$24/(1+Assumptions!$B$24)/Assumptions!$B$54,MAX(Assumptions!$B$44,AE12)))) | AF13: =U13-U12 | AG13: =IFERROR(U13/AE13,0) | AH13: =MAX(0,AE13-AE12) | AI13: =MAX(AD12-Z13,0) | AJ13: =AI13*Assumptions!$B$46/12 | AK13: =AD12+Q13-R13-I13+K13+AF13-V13+AJ13-AP13 | AL13: =TRIM(IF(AH13>0,"Increase warehouse facility to $"&TEXT(AE13,"#,##0")&" (from $"&TEXT(AE12,"#,##0")&"). ","")&IF(AC13>0,"Raise ~$"&TEXT(AC13,"#,##0")&" of equity — annual raise, funds the next 12 months.","")) | AM13: =Q13-R13-I13+K13+AF13-V13-AP13 | AN13: =SUM($H$4:H13) | AO13: =H13*Assumptions!$B$16 | AP13: =MAX(AO13*Assumptions!$B$62,Assumptions!$B$63)+Assumptions!$B$64/12 | AQ13: =(O13+P13)*Assumptions!$B$61/(1-Assumptions!$B$61)
A14: 11 | B14: =EDATE(Assumptions!$B$4,10) | C14: =INT((A14-1)/12)+1 | D14: =IF(C14=1,Assumptions!$B$6,IF(C14=2,Assumptions!$B$7,IF(C14=3,Assumptions!$B$8,IF(C14=4,Assumptions!$B$9,Assumptions!$B$10)))) | E14: =ROUND(F13*Assumptions!$B$11,0) | F14: =F13+D14-E14 | G14: =ROUND(F14*Assumptions!$B$14*(365/12/7),0) | H14: =ROUND(G14*Assumptions!$B$15,0) | I14: =AO14*(1-Assumptions!$B$61) | J14: =M13 | K14: =IFERROR(J14/Assumptions!$B$17,0) | L14: =J14*Assumptions!$B$20/12 | M14: =MAX(J14+I14-K14-L14,0) | N14: =(J14+M14)/2 | O14: =N14*Assumptions!$B$18/12 | P14: =I14*Assumptions!$B$19 | Q14: =O14+P14 | R14: =Assumptions!$B$33*(1+Assumptions!$B$34)^(C14-1)/12 | S14: =L14 | T14: =Q14-R14-S14-AP14 | U14: =MIN(AE14,M14*Assumptions!$B$24/(1+Assumptions!$B$24)) | V14: =((U14+U13)/2)*Assumptions!$B$23/12 | W14: =T14-V14+AJ14 | X14: =X13+W14 | Y14: =MAX(M14-U14,0) | Z14: =R14*Assumptions!$B$25 | AA14: =Y14+Z14 | AB14: =MAX(AB13,AA14) | AC14: 0 | AD14: =AK14+AC14 | AE14: =IF(SUM($H$4:H14)<Assumptions!$B$57,0,MAX(MAX(Assumptions!$B$44,AE13),IF(M14*Assumptions!$B$24/(1+Assumptions!$B$24)>MAX(Assumptions!$B$44,AE13)*Assumptions!$B$53,M14*Assumptions!$B$24/(1+Assumptions!$B$24)/Assumptions!$B$54,MAX(Assumptions!$B$44,AE13)))) | AF14: =U14-U13 | AG14: =IFERROR(U14/AE14,0) | AH14: =MAX(0,AE14-AE13) | AI14: =MAX(AD13-Z14,0) | AJ14: =AI14*Assumptions!$B$46/12 | AK14: =AD13+Q14-R14-I14+K14+AF14-V14+AJ14-AP14 | AL14: =TRIM(IF(AH14>0,"Increase warehouse facility to $"&TEXT(AE14,"#,##0")&" (from $"&TEXT(AE13,"#,##0")&"). ","")&IF(AC14>0,"Raise ~$"&TEXT(AC14,"#,##0")&" of equity — annual raise, funds the next 12 months.","")) | AM14: =Q14-R14-I14+K14+AF14-V14-AP14 | AN14: =SUM($H$4:H14) | AO14: =H14*Assumptions!$B$16 | AP14: =MAX(AO14*Assumptions!$B$62,Assumptions!$B$63)+Assumptions!$B$64/12 | AQ14: =(O14+P14)*Assumptions!$B$61/(1-Assumptions!$B$61)
A15: 12 | B15: =EDATE(Assumptions!$B$4,11) | C15: =INT((A15-1)/12)+1 | D15: =IF(C15=1,Assumptions!$B$6,IF(C15=2,Assumptions!$B$7,IF(C15=3,Assumptions!$B$8,IF(C15=4,Assumptions!$B$9,Assumptions!$B$10)))) | E15: =ROUND(F14*Assumptions!$B$11,0) | F15: =F14+D15-E15 | G15: =ROUND(F15*Assumptions!$B$14*(365/12/7),0) | H15: =ROUND(G15*Assumptions!$B$15,0) | I15: =AO15*(1-Assumptions!$B$61) | J15: =M14 | K15: =IFERROR(J15/Assumptions!$B$17,0) | L15: =J15*Assumptions!$B$20/12 | M15: =MAX(J15+I15-K15-L15,0) | N15: =(J15+M15)/2 | O15: =N15*Assumptions!$B$18/12 | P15: =I15*Assumptions!$B$19 | Q15: =O15+P15 | R15: =Assumptions!$B$33*(1+Assumptions!$B$34)^(C15-1)/12 | S15: =L15 | T15: =Q15-R15-S15-AP15 | U15: =MIN(AE15,M15*Assumptions!$B$24/(1+Assumptions!$B$24)) | V15: =((U15+U14)/2)*Assumptions!$B$23/12 | W15: =T15-V15+AJ15 | X15: =X14+W15 | Y15: =MAX(M15-U15,0) | Z15: =R15*Assumptions!$B$25 | AA15: =Y15+Z15 | AB15: =MAX(AB14,AA15) | AC15: 0 | AD15: =AK15+AC15 | AE15: =IF(SUM($H$4:H15)<Assumptions!$B$57,0,MAX(MAX(Assumptions!$B$44,AE14),IF(M15*Assumptions!$B$24/(1+Assumptions!$B$24)>MAX(Assumptions!$B$44,AE14)*Assumptions!$B$53,M15*Assumptions!$B$24/(1+Assumptions!$B$24)/Assumptions!$B$54,MAX(Assumptions!$B$44,AE14)))) | AF15: =U15-U14 | AG15: =IFERROR(U15/AE15,0) | AH15: =MAX(0,AE15-AE14) | AI15: =MAX(AD14-Z15,0) | AJ15: =AI15*Assumptions!$B$46/12 | AK15: =AD14+Q15-R15-I15+K15+AF15-V15+AJ15-AP15 | AL15: =TRIM(IF(AH15>0,"Increase warehouse facility to $"&TEXT(AE15,"#,##0")&" (from $"&TEXT(AE14,"#,##0")&"). ","")&IF(AC15>0,"Raise ~$"&TEXT(AC15,"#,##0")&" of equity — annual raise, funds the next 12 months.","")) | AM15: =Q15-R15-I15+K15+AF15-V15-AP15 | AN15: =SUM($H$4:H15) | AO15: =H15*Assumptions!$B$16 | AP15: =MAX(AO15*Assumptions!$B$62,Assumptions!$B$63)+Assumptions!$B$64/12 | AQ15: =(O15+P15)*Assumptions!$B$61/(1-Assumptions!$B$61)
A16: 13 | B16: =EDATE(Assumptions!$B$4,12) | C16: =INT((A16-1)/12)+1 | D16: =IF(C16=1,Assumptions!$B$6,IF(C16=2,Assumptions!$B$7,IF(C16=3,Assumptions!$B$8,IF(C16=4,Assumptions!$B$9,Assumptions!$B$10)))) | E16: =ROUND(F15*Assumptions!$B$11,0) | F16: =F15+D16-E16 | G16: =ROUND(F16*Assumptions!$B$14*(365/12/7),0) | H16: =ROUND(G16*Assumptions!$B$15,0) | I16: =AO16*(1-Assumptions!$B$61) | J16: =M15 | K16: =IFERROR(J16/Assumptions!$B$17,0) | L16: =J16*Assumptions!$B$20/12 | M16: =MAX(J16+I16-K16-L16,0) | N16: =(J16+M16)/2 | O16: =N16*Assumptions!$B$18/12 | P16: =I16*Assumptions!$B$19 | Q16: =O16+P16 | R16: =Assumptions!$B$33*(1+Assumptions!$B$34)^(C16-1)/12 | S16: =L16 | T16: =Q16-R16-S16-AP16 | U16: =MIN(AE16,M16*Assumptions!$B$24/(1+Assumptions!$B$24)) | V16: =((U16+U15)/2)*Assumptions!$B$23/12 | W16: =T16-V16+AJ16 | X16: =X15+W16 | Y16: =MAX(M16-U16,0) | Z16: =R16*Assumptions!$B$25 | AA16: =Y16+Z16 | AB16: =MAX(AB15,AA16) | AC16: =MAX(0,MAX(Z16-AD15-AM16,Z17-AD15-SUM(AM16:AM17),Z18-AD15-SUM(AM16:AM18),Z19-AD15-SUM(AM16:AM19),Z20-AD15-SUM(AM16:AM20),Z21-AD15-SUM(AM16:AM21),Z22-AD15-SUM(AM16:AM22),Z23-AD15-SUM(AM16:AM23),Z24-AD15-SUM(AM16:AM24),Z25-AD15-SUM(AM16:AM25),Z26-AD15-SUM(AM16:AM26),Z27-AD15-SUM(AM16:AM27))) | AD16: =AK16+AC16 | AE16: =IF(SUM($H$4:H16)<Assumptions!$B$57,0,MAX(MAX(Assumptions!$B$44,AE15),IF(M16*Assumptions!$B$24/(1+Assumptions!$B$24)>MAX(Assumptions!$B$44,AE15)*Assumptions!$B$53,M16*Assumptions!$B$24/(1+Assumptions!$B$24)/Assumptions!$B$54,MAX(Assumptions!$B$44,AE15)))) | AF16: =U16-U15 | AG16: =IFERROR(U16/AE16,0) | AH16: =MAX(0,AE16-AE15) | AI16: =MAX(AD15-Z16,0) | AJ16: =AI16*Assumptions!$B$46/12 | AK16: =AD15+Q16-R16-I16+K16+AF16-V16+AJ16-AP16 | AL16: =TRIM(IF(AH16>0,"Increase warehouse facility to $"&TEXT(AE16,"#,##0")&" (from $"&TEXT(AE15,"#,##0")&"). ","")&IF(AC16>0,"Raise ~$"&TEXT(AC16,"#,##0")&" of equity — annual raise, funds the next 12 months.","")) | AM16: =Q16-R16-I16+K16+AF16-V16-AP16 | AN16: =SUM($H$4:H16) | AO16: =H16*Assumptions!$B$16 | AP16: =MAX(AO16*Assumptions!$B$62,Assumptions!$B$63)+Assumptions!$B$64/12 | AQ16: =(O16+P16)*Assumptions!$B$61/(1-Assumptions!$B$61)
A17: 14 | B17: =EDATE(Assumptions!$B$4,13) | C17: =INT((A17-1)/12)+1 | D17: =IF(C17=1,Assumptions!$B$6,IF(C17=2,Assumptions!$B$7,IF(C17=3,Assumptions!$B$8,IF(C17=4,Assumptions!$B$9,Assumptions!$B$10)))) | E17: =ROUND(F16*Assumptions!$B$11,0) | F17: =F16+D17-E17 | G17: =ROUND(F17*Assumptions!$B$14*(365/12/7),0) | H17: =ROUND(G17*Assumptions!$B$15,0) | I17: =AO17*(1-Assumptions!$B$61) | J17: =M16 | K17: =IFERROR(J17/Assumptions!$B$17,0) | L17: =J17*Assumptions!$B$20/12 | M17: =MAX(J17+I17-K17-L17,0) | N17: =(J17+M17)/2 | O17: =N17*Assumptions!$B$18/12 | P17: =I17*Assumptions!$B$19 | Q17: =O17+P17 | R17: =Assumptions!$B$33*(1+Assumptions!$B$34)^(C17-1)/12 | S17: =L17 | T17: =Q17-R17-S17-AP17 | U17: =MIN(AE17,M17*Assumptions!$B$24/(1+Assumptions!$B$24)) | V17: =((U17+U16)/2)*Assumptions!$B$23/12 | W17: =T17-V17+AJ17 | X17: =X16+W17 | Y17: =MAX(M17-U17,0) | Z17: =R17*Assumptions!$B$25 | AA17: =Y17+Z17 | AB17: =MAX(AB16,AA17) | AC17: 0 | AD17: =AK17+AC17 | AE17: =IF(SUM($H$4:H17)<Assumptions!$B$57,0,MAX(MAX(Assumptions!$B$44,AE16),IF(M17*Assumptions!$B$24/(1+Assumptions!$B$24)>MAX(Assumptions!$B$44,AE16)*Assumptions!$B$53,M17*Assumptions!$B$24/(1+Assumptions!$B$24)/Assumptions!$B$54,MAX(Assumptions!$B$44,AE16)))) | AF17: =U17-U16 | AG17: =IFERROR(U17/AE17,0) | AH17: =MAX(0,AE17-AE16) | AI17: =MAX(AD16-Z17,0) | AJ17: =AI17*Assumptions!$B$46/12 | AK17: =AD16+Q17-R17-I17+K17+AF17-V17+AJ17-AP17 | AL17: =TRIM(IF(AH17>0,"Increase warehouse facility to $"&TEXT(AE17,"#,##0")&" (from $"&TEXT(AE16,"#,##0")&"). ","")&IF(AC17>0,"Raise ~$"&TEXT(AC17,"#,##0")&" of equity — annual raise, funds the next 12 months.","")) | AM17: =Q17-R17-I17+K17+AF17-V17-AP17 | AN17: =SUM($H$4:H17) | AO17: =H17*Assumptions!$B$16 | AP17: =MAX(AO17*Assumptions!$B$62,Assumptions!$B$63)+Assumptions!$B$64/12 | AQ17: =(O17+P17)*Assumptions!$B$61/(1-Assumptions!$B$61)
A18: 15 | B18: =EDATE(Assumptions!$B$4,14) | C18: =INT((A18-1)/12)+1 | D18: =IF(C18=1,Assumptions!$B$6,IF(C18=2,Assumptions!$B$7,IF(C18=3,Assumptions!$B$8,IF(C18=4,Assumptions!$B$9,Assumptions!$B$10)))) | E18: =ROUND(F17*Assumptions!$B$11,0) | F18: =F17+D18-E18 | G18: =ROUND(F18*Assumptions!$B$14*(365/12/7),0) | H18: =ROUND(G18*Assumptions!$B$15,0) | I18: =AO18*(1-Assumptions!$B$61) | J18: =M17 | K18: =IFERROR(J18/Assumptions!$B$17,0) | L18: =J18*Assumptions!$B$20/12 | M18: =MAX(J18+I18-K18-L18,0) | N18: =(J18+M18)/2 | O18: =N18*Assumptions!$B$18/12 | P18: =I18*Assumptions!$B$19 | Q18: =O18+P18 | R18: =Assumptions!$B$33*(1+Assumptions!$B$34)^(C18-1)/12 | S18: =L18 | T18: =Q18-R18-S18-AP18 | U18: =MIN(AE18,M18*Assumptions!$B$24/(1+Assumptions!$B$24)) | V18: =((U18+U17)/2)*Assumptions!$B$23/12 | W18: =T18-V18+AJ18 | X18: =X17+W18 | Y18: =MAX(M18-U18,0) | Z18: =R18*Assumptions!$B$25 | AA18: =Y18+Z18 | AB18: =MAX(AB17,AA18) | AC18: 0 | AD18: =AK18+AC18 | AE18: =IF(SUM($H$4:H18)<Assumptions!$B$57,0,MAX(MAX(Assumptions!$B$44,AE17),IF(M18*Assumptions!$B$24/(1+Assumptions!$B$24)>MAX(Assumptions!$B$44,AE17)*Assumptions!$B$53,M18*Assumptions!$B$24/(1+Assumptions!$B$24)/Assumptions!$B$54,MAX(Assumptions!$B$44,AE17)))) | AF18: =U18-U17 | AG18: =IFERROR(U18/AE18,0) | AH18: =MAX(0,AE18-AE17) | AI18: =MAX(AD17-Z18,0) | AJ18: =AI18*Assumptions!$B$46/12 | AK18: =AD17+Q18-R18-I18+K18+AF18-V18+AJ18-AP18 | AL18: =TRIM(IF(AH18>0,"Increase warehouse facility to $"&TEXT(AE18,"#,##0")&" (from $"&TEXT(AE17,"#,##0")&"). ","")&IF(AC18>0,"Raise ~$"&TEXT(AC18,"#,##0")&" of equity — annual raise, funds the next 12 months.","")) | AM18: =Q18-R18-I18+K18+AF18-V18-AP18 | AN18: =SUM($H$4:H18) | AO18: =H18*Assumptions!$B$16 | AP18: =MAX(AO18*Assumptions!$B$62,Assumptions!$B$63)+Assumptions!$B$64/12 | AQ18: =(O18+P18)*Assumptions!$B$61/(1-Assumptions!$B$61)
A19: 16 | B19: =EDATE(Assumptions!$B$4,15) | C19: =INT((A19-1)/12)+1 | D19: =IF(C19=1,Assumptions!$B$6,IF(C19=2,Assumptions!$B$7,IF(C19=3,Assumptions!$B$8,IF(C19=4,Assumptions!$B$9,Assumptions!$B$10)))) | E19: =ROUND(F18*Assumptions!$B$11,0) | F19: =F18+D19-E19 | G19: =ROUND(F19*Assumptions!$B$14*(365/12/7),0) | H19: =ROUND(G19*Assumptions!$B$15,0) | I19: =AO19*(1-Assumptions!$B$61) | J19: =M18 | K19: =IFERROR(J19/Assumptions!$B$17,0) | L19: =J19*Assumptions!$B$20/12 | M19: =MAX(J19+I19-K19-L19,0) | N19: =(J19+M19)/2 | O19: =N19*Assumptions!$B$18/12 | P19: =I19*Assumptions!$B$19 | Q19: =O19+P19 | R19: =Assumptions!$B$33*(1+Assumptions!$B$34)^(C19-1)/12 | S19: =L19 | T19: =Q19-R19-S19-AP19 | U19: =MIN(AE19,M19*Assumptions!$B$24/(1+Assumptions!$B$24)) | V19: =((U19+U18)/2)*Assumptions!$B$23/12 | W19: =T19-V19+AJ19 | X19: =X18+W19 | Y19: =MAX(M19-U19,0) | Z19: =R19*Assumptions!$B$25 | AA19: =Y19+Z19 | AB19: =MAX(AB18,AA19) | AC19: 0 | AD19: =AK19+AC19 | AE19: =IF(SUM($H$4:H19)<Assumptions!$B$57,0,MAX(MAX(Assumptions!$B$44,AE18),IF(M19*Assumptions!$B$24/(1+Assumptions!$B$24)>MAX(Assumptions!$B$44,AE18)*Assumptions!$B$53,M19*Assumptions!$B$24/(1+Assumptions!$B$24)/Assumptions!$B$54,MAX(Assumptions!$B$44,AE18)))) | AF19: =U19-U18 | AG19: =IFERROR(U19/AE19,0) | AH19: =MAX(0,AE19-AE18) | AI19: =MAX(AD18-Z19,0) | AJ19: =AI19*Assumptions!$B$46/12 | AK19: =AD18+Q19-R19-I19+K19+AF19-V19+AJ19-AP19 | AL19: =TRIM(IF(AH19>0,"Increase warehouse facility to $"&TEXT(AE19,"#,##0")&" (from $"&TEXT(AE18,"#,##0")&"). ","")&IF(AC19>0,"Raise ~$"&TEXT(AC19,"#,##0")&" of equity — annual raise, funds the next 12 months.","")) | AM19: =Q19-R19-I19+K19+AF19-V19-AP19 | AN19: =SUM($H$4:H19) | AO19: =H19*Assumptions!$B$16 | AP19: =MAX(AO19*Assumptions!$B$62,Assumptions!$B$63)+Assumptions!$B$64/12 | AQ19: =(O19+P19)*Assumptions!$B$61/(1-Assumptions!$B$61)
A20: 17 | B20: =EDATE(Assumptions!$B$4,16) | C20: =INT((A20-1)/12)+1 | D20: =IF(C20=1,Assumptions!$B$6,IF(C20=2,Assumptions!$B$7,IF(C20=3,Assumptions!$B$8,IF(C20=4,Assumptions!$B$9,Assumptions!$B$10)))) | E20: =ROUND(F19*Assumptions!$B$11,0) | F20: =F19+D20-E20 | G20: =ROUND(F20*Assumptions!$B$14*(365/12/7),0) | H20: =ROUND(G20*Assumptions!$B$15,0) | I20: =AO20*(1-Assumptions!$B$61) | J20: =M19 | K20: =IFERROR(J20/Assumptions!$B$17,0) | L20: =J20*Assumptions!$B$20/12 | M20: =MAX(J20+I20-K20-L20,0) | N20: =(J20+M20)/2 | O20: =N20*Assumptions!$B$18/12 | P20: =I20*Assumptions!$B$19 | Q20: =O20+P20 | R20: =Assumptions!$B$33*(1+Assumptions!$B$34)^(C20-1)/12 | S20: =L20 | T20: =Q20-R20-S20-AP20 | U20: =MIN(AE20,M20*Assumptions!$B$24/(1+Assumptions!$B$24)) | V20: =((U20+U19)/2)*Assumptions!$B$23/12 | W20: =T20-V20+AJ20 | X20: =X19+W20 | Y20: =MAX(M20-U20,0) | Z20: =R20*Assumptions!$B$25 | AA20: =Y20+Z20 | AB20: =MAX(AB19,AA20) | AC20: 0 | AD20: =AK20+AC20 | AE20: =IF(SUM($H$4:H20)<Assumptions!$B$57,0,MAX(MAX(Assumptions!$B$44,AE19),IF(M20*Assumptions!$B$24/(1+Assumptions!$B$24)>MAX(Assumptions!$B$44,AE19)*Assumptions!$B$53,M20*Assumptions!$B$24/(1+Assumptions!$B$24)/Assumptions!$B$54,MAX(Assumptions!$B$44,AE19)))) | AF20: =U20-U19 | AG20: =IFERROR(U20/AE20,0) | AH20: =MAX(0,AE20-AE19) | AI20: =MAX(AD19-Z20,0) | AJ20: =AI20*Assumptions!$B$46/12 | AK20: =AD19+Q20-R20-I20+K20+AF20-V20+AJ20-AP20 | AL20: =TRIM(IF(AH20>0,"Increase warehouse facility to $"&TEXT(AE20,"#,##0")&" (from $"&TEXT(AE19,"#,##0")&"). ","")&IF(AC20>0,"Raise ~$"&TEXT(AC20,"#,##0")&" of equity — annual raise, funds the next 12 months.","")) | AM20: =Q20-R20-I20+K20+AF20-V20-AP20 | AN20: =SUM($H$4:H20) | AO20: =H20*Assumptions!$B$16 | AP20: =MAX(AO20*Assumptions!$B$62,Assumptions!$B$63)+Assumptions!$B$64/12 | AQ20: =(O20+P20)*Assumptions!$B$61/(1-Assumptions!$B$61)
A21: 18 | B21: =EDATE(Assumptions!$B$4,17) | C21: =INT((A21-1)/12)+1 | D21: =IF(C21=1,Assumptions!$B$6,IF(C21=2,Assumptions!$B$7,IF(C21=3,Assumptions!$B$8,IF(C21=4,Assumptions!$B$9,Assumptions!$B$10)))) | E21: =ROUND(F20*Assumptions!$B$11,0) | F21: =F20+D21-E21 | G21: =ROUND(F21*Assumptions!$B$14*(365/12/7),0) | H21: =ROUND(G21*Assumptions!$B$15,0) | I21: =AO21*(1-Assumptions!$B$61) | J21: =M20 | K21: =IFERROR(J21/Assumptions!$B$17,0) | L21: =J21*Assumptions!$B$20/12 | M21: =MAX(J21+I21-K21-L21,0) | N21: =(J21+M21)/2 | O21: =N21*Assumptions!$B$18/12 | P21: =I21*Assumptions!$B$19 | Q21: =O21+P21 | R21: =Assumptions!$B$33*(1+Assumptions!$B$34)^(C21-1)/12 | S21: =L21 | T21: =Q21-R21-S21-AP21 | U21: =MIN(AE21,M21*Assumptions!$B$24/(1+Assumptions!$B$24)) | V21: =((U21+U20)/2)*Assumptions!$B$23/12 | W21: =T21-V21+AJ21 | X21: =X20+W21 | Y21: =MAX(M21-U21,0) | Z21: =R21*Assumptions!$B$25 | AA21: =Y21+Z21 | AB21: =MAX(AB20,AA21) | AC21: 0 | AD21: =AK21+AC21 | AE21: =IF(SUM($H$4:H21)<Assumptions!$B$57,0,MAX(MAX(Assumptions!$B$44,AE20),IF(M21*Assumptions!$B$24/(1+Assumptions!$B$24)>MAX(Assumptions!$B$44,AE20)*Assumptions!$B$53,M21*Assumptions!$B$24/(1+Assumptions!$B$24)/Assumptions!$B$54,MAX(Assumptions!$B$44,AE20)))) | AF21: =U21-U20 | AG21: =IFERROR(U21/AE21,0) | AH21: =MAX(0,AE21-AE20) | AI21: =MAX(AD20-Z21,0) | AJ21: =AI21*Assumptions!$B$46/12 | AK21: =AD20+Q21-R21-I21+K21+AF21-V21+AJ21-AP21 | AL21: =TRIM(IF(AH21>0,"Increase warehouse facility to $"&TEXT(AE21,"#,##0")&" (from $"&TEXT(AE20,"#,##0")&"). ","")&IF(AC21>0,"Raise ~$"&TEXT(AC21,"#,##0")&" of equity — annual raise, funds the next 12 months.","")) | AM21: =Q21-R21-I21+K21+AF21-V21-AP21 | AN21: =SUM($H$4:H21) | AO21: =H21*Assumptions!$B$16 | AP21: =MAX(AO21*Assumptions!$B$62,Assumptions!$B$63)+Assumptions!$B$64/12 | AQ21: =(O21+P21)*Assumptions!$B$61/(1-Assumptions!$B$61)
A22: 19 | B22: =EDATE(Assumptions!$B$4,18) | C22: =INT((A22-1)/12)+1 | D22: =IF(C22=1,Assumptions!$B$6,IF(C22=2,Assumptions!$B$7,IF(C22=3,Assumptions!$B$8,IF(C22=4,Assumptions!$B$9,Assumptions!$B$10)))) | E22: =ROUND(F21*Assumptions!$B$11,0) | F22: =F21+D22-E22 | G22: =ROUND(F22*Assumptions!$B$14*(365/12/7),0) | H22: =ROUND(G22*Assumptions!$B$15,0) | I22: =AO22*(1-Assumptions!$B$61) | J22: =M21 | K22: =IFERROR(J22/Assumptions!$B$17,0) | L22: =J22*Assumptions!$B$20/12 | M22: =MAX(J22+I22-K22-L22,0) | N22: =(J22+M22)/2 | O22: =N22*Assumptions!$B$18/12 | P22: =I22*Assumptions!$B$19 | Q22: =O22+P22 | R22: =Assumptions!$B$33*(1+Assumptions!$B$34)^(C22-1)/12 | S22: =L22 | T22: =Q22-R22-S22-AP22 | U22: =MIN(AE22,M22*Assumptions!$B$24/(1+Assumptions!$B$24)) | V22: =((U22+U21)/2)*Assumptions!$B$23/12 | W22: =T22-V22+AJ22 | X22: =X21+W22 | Y22: =MAX(M22-U22,0) | Z22: =R22*Assumptions!$B$25 | AA22: =Y22+Z22 | AB22: =MAX(AB21,AA22) | AC22: 0 | AD22: =AK22+AC22 | AE22: =IF(SUM($H$4:H22)<Assumptions!$B$57,0,MAX(MAX(Assumptions!$B$44,AE21),IF(M22*Assumptions!$B$24/(1+Assumptions!$B$24)>MAX(Assumptions!$B$44,AE21)*Assumptions!$B$53,M22*Assumptions!$B$24/(1+Assumptions!$B$24)/Assumptions!$B$54,MAX(Assumptions!$B$44,AE21)))) | AF22: =U22-U21 | AG22: =IFERROR(U22/AE22,0) | AH22: =MAX(0,AE22-AE21) | AI22: =MAX(AD21-Z22,0) | AJ22: =AI22*Assumptions!$B$46/12 | AK22: =AD21+Q22-R22-I22+K22+AF22-V22+AJ22-AP22 | AL22: =TRIM(IF(AH22>0,"Increase warehouse facility to $"&TEXT(AE22,"#,##0")&" (from $"&TEXT(AE21,"#,##0")&"). ","")&IF(AC22>0,"Raise ~$"&TEXT(AC22,"#,##0")&" of equity — annual raise, funds the next 12 months.","")) | AM22: =Q22-R22-I22+K22+AF22-V22-AP22 | AN22: =SUM($H$4:H22) | AO22: =H22*Assumptions!$B$16 | AP22: =MAX(AO22*Assumptions!$B$62,Assumptions!$B$63)+Assumptions!$B$64/12 | AQ22: =(O22+P22)*Assumptions!$B$61/(1-Assumptions!$B$61)
A23: 20 | B23: =EDATE(Assumptions!$B$4,19) | C23: =INT((A23-1)/12)+1 | D23: =IF(C23=1,Assumptions!$B$6,IF(C23=2,Assumptions!$B$7,IF(C23=3,Assumptions!$B$8,IF(C23=4,Assumptions!$B$9,Assumptions!$B$10)))) | E23: =ROUND(F22*Assumptions!$B$11,0) | F23: =F22+D23-E23 | G23: =ROUND(F23*Assumptions!$B$14*(365/12/7),0) | H23: =ROUND(G23*Assumptions!$B$15,0) | I23: =AO23*(1-Assumptions!$B$61) | J23: =M22 | K23: =IFERROR(J23/Assumptions!$B$17,0) | L23: =J23*Assumptions!$B$20/12 | M23: =MAX(J23+I23-K23-L23,0) | N23: =(J23+M23)/2 | O23: =N23*Assumptions!$B$18/12 | P23: =I23*Assumptions!$B$19 | Q23: =O23+P23 | R23: =Assumptions!$B$33*(1+Assumptions!$B$34)^(C23-1)/12 | S23: =L23 | T23: =Q23-R23-S23-AP23 | U23: =MIN(AE23,M23*Assumptions!$B$24/(1+Assumptions!$B$24)) | V23: =((U23+U22)/2)*Assumptions!$B$23/12 | W23: =T23-V23+AJ23 | X23: =X22+W23 | Y23: =MAX(M23-U23,0) | Z23: =R23*Assumptions!$B$25 | AA23: =Y23+Z23 | AB23: =MAX(AB22,AA23) | AC23: 0 | AD23: =AK23+AC23 | AE23: =IF(SUM($H$4:H23)<Assumptions!$B$57,0,MAX(MAX(Assumptions!$B$44,AE22),IF(M23*Assumptions!$B$24/(1+Assumptions!$B$24)>MAX(Assumptions!$B$44,AE22)*Assumptions!$B$53,M23*Assumptions!$B$24/(1+Assumptions!$B$24)/Assumptions!$B$54,MAX(Assumptions!$B$44,AE22)))) | AF23: =U23-U22 | AG23: =IFERROR(U23/AE23,0) | AH23: =MAX(0,AE23-AE22) | AI23: =MAX(AD22-Z23,0) | AJ23: =AI23*Assumptions!$B$46/12 | AK23: =AD22+Q23-R23-I23+K23+AF23-V23+AJ23-AP23 | AL23: =TRIM(IF(AH23>0,"Increase warehouse facility to $"&TEXT(AE23,"#,##0")&" (from $"&TEXT(AE22,"#,##0")&"). ","")&IF(AC23>0,"Raise ~$"&TEXT(AC23,"#,##0")&" of equity — annual raise, funds the next 12 months.","")) | AM23: =Q23-R23-I23+K23+AF23-V23-AP23 | AN23: =SUM($H$4:H23) | AO23: =H23*Assumptions!$B$16 | AP23: =MAX(AO23*Assumptions!$B$62,Assumptions!$B$63)+Assumptions!$B$64/12 | AQ23: =(O23+P23)*Assumptions!$B$61/(1-Assumptions!$B$61)
A24: 21 | B24: =EDATE(Assumptions!$B$4,20) | C24: =INT((A24-1)/12)+1 | D24: =IF(C24=1,Assumptions!$B$6,IF(C24=2,Assumptions!$B$7,IF(C24=3,Assumptions!$B$8,IF(C24=4,Assumptions!$B$9,Assumptions!$B$10)))) | E24: =ROUND(F23*Assumptions!$B$11,0) | F24: =F23+D24-E24 | G24: =ROUND(F24*Assumptions!$B$14*(365/12/7),0) | H24: =ROUND(G24*Assumptions!$B$15,0) | I24: =AO24*(1-Assumptions!$B$61) | J24: =M23 | K24: =IFERROR(J24/Assumptions!$B$17,0) | L24: =J24*Assumptions!$B$20/12 | M24: =MAX(J24+I24-K24-L24,0) | N24: =(J24+M24)/2 | O24: =N24*Assumptions!$B$18/12 | P24: =I24*Assumptions!$B$19 | Q24: =O24+P24 | R24: =Assumptions!$B$33*(1+Assumptions!$B$34)^(C24-1)/12 | S24: =L24 | T24: =Q24-R24-S24-AP24 | U24: =MIN(AE24,M24*Assumptions!$B$24/(1+Assumptions!$B$24)) | V24: =((U24+U23)/2)*Assumptions!$B$23/12 | W24: =T24-V24+AJ24 | X24: =X23+W24 | Y24: =MAX(M24-U24,0) | Z24: =R24*Assumptions!$B$25 | AA24: =Y24+Z24 | AB24: =MAX(AB23,AA24) | AC24: 0 | AD24: =AK24+AC24 | AE24: =IF(SUM($H$4:H24)<Assumptions!$B$57,0,MAX(MAX(Assumptions!$B$44,AE23),IF(M24*Assumptions!$B$24/(1+Assumptions!$B$24)>MAX(Assumptions!$B$44,AE23)*Assumptions!$B$53,M24*Assumptions!$B$24/(1+Assumptions!$B$24)/Assumptions!$B$54,MAX(Assumptions!$B$44,AE23)))) | AF24: =U24-U23 | AG24: =IFERROR(U24/AE24,0) | AH24: =MAX(0,AE24-AE23) | AI24: =MAX(AD23-Z24,0) | AJ24: =AI24*Assumptions!$B$46/12 | AK24: =AD23+Q24-R24-I24+K24+AF24-V24+AJ24-AP24 | AL24: =TRIM(IF(AH24>0,"Increase warehouse facility to $"&TEXT(AE24,"#,##0")&" (from $"&TEXT(AE23,"#,##0")&"). ","")&IF(AC24>0,"Raise ~$"&TEXT(AC24,"#,##0")&" of equity — annual raise, funds the next 12 months.","")) | AM24: =Q24-R24-I24+K24+AF24-V24-AP24 | AN24: =SUM($H$4:H24) | AO24: =H24*Assumptions!$B$16 | AP24: =MAX(AO24*Assumptions!$B$62,Assumptions!$B$63)+Assumptions!$B$64/12 | AQ24: =(O24+P24)*Assumptions!$B$61/(1-Assumptions!$B$61)
A25: 22 | B25: =EDATE(Assumptions!$B$4,21) | C25: =INT((A25-1)/12)+1 | D25: =IF(C25=1,Assumptions!$B$6,IF(C25=2,Assumptions!$B$7,IF(C25=3,Assumptions!$B$8,IF(C25=4,Assumptions!$B$9,Assumptions!$B$10)))) | E25: =ROUND(F24*Assumptions!$B$11,0) | F25: =F24+D25-E25 | G25: =ROUND(F25*Assumptions!$B$14*(365/12/7),0) | H25: =ROUND(G25*Assumptions!$B$15,0) | I25: =AO25*(1-Assumptions!$B$61) | J25: =M24 | K25: =IFERROR(J25/Assumptions!$B$17,0) | L25: =J25*Assumptions!$B$20/12 | M25: =MAX(J25+I25-K25-L25,0) | N25: =(J25+M25)/2 | O25: =N25*Assumptions!$B$18/12 | P25: =I25*Assumptions!$B$19 | Q25: =O25+P25 | R25: =Assumptions!$B$33*(1+Assumptions!$B$34)^(C25-1)/12 | S25: =L25 | T25: =Q25-R25-S25-AP25 | U25: =MIN(AE25,M25*Assumptions!$B$24/(1+Assumptions!$B$24)) | V25: =((U25+U24)/2)*Assumptions!$B$23/12 | W25: =T25-V25+AJ25 | X25: =X24+W25 | Y25: =MAX(M25-U25,0) | Z25: =R25*Assumptions!$B$25 | AA25: =Y25+Z25 | AB25: =MAX(AB24,AA25) | AC25: 0 | AD25: =AK25+AC25 | AE25: =IF(SUM($H$4:H25)<Assumptions!$B$57,0,MAX(MAX(Assumptions!$B$44,AE24),IF(M25*Assumptions!$B$24/(1+Assumptions!$B$24)>MAX(Assumptions!$B$44,AE24)*Assumptions!$B$53,M25*Assumptions!$B$24/(1+Assumptions!$B$24)/Assumptions!$B$54,MAX(Assumptions!$B$44,AE24)))) | AF25: =U25-U24 | AG25: =IFERROR(U25/AE25,0) | AH25: =MAX(0,AE25-AE24) | AI25: =MAX(AD24-Z25,0) | AJ25: =AI25*Assumptions!$B$46/12 | AK25: =AD24+Q25-R25-I25+K25+AF25-V25+AJ25-AP25 | AL25: =TRIM(IF(AH25>0,"Increase warehouse facility to $"&TEXT(AE25,"#,##0")&" (from $"&TEXT(AE24,"#,##0")&"). ","")&IF(AC25>0,"Raise ~$"&TEXT(AC25,"#,##0")&" of equity — annual raise, funds the next 12 months.","")) | AM25: =Q25-R25-I25+K25+AF25-V25-AP25 | AN25: =SUM($H$4:H25) | AO25: =H25*Assumptions!$B$16 | AP25: =MAX(AO25*Assumptions!$B$62,Assumptions!$B$63)+Assumptions!$B$64/12 | AQ25: =(O25+P25)*Assumptions!$B$61/(1-Assumptions!$B$61)
A26: 23 | B26: =EDATE(Assumptions!$B$4,22) | C26: =INT((A26-1)/12)+1 | D26: =IF(C26=1,Assumptions!$B$6,IF(C26=2,Assumptions!$B$7,IF(C26=3,Assumptions!$B$8,IF(C26=4,Assumptions!$B$9,Assumptions!$B$10)))) | E26: =ROUND(F25*Assumptions!$B$11,0) | F26: =F25+D26-E26 | G26: =ROUND(F26*Assumptions!$B$14*(365/12/7),0) | H26: =ROUND(G26*Assumptions!$B$15,0) | I26: =AO26*(1-Assumptions!$B$61) | J26: =M25 | K26: =IFERROR(J26/Assumptions!$B$17,0) | L26: =J26*Assumptions!$B$20/12 | M26: =MAX(J26+I26-K26-L26,0) | N26: =(J26+M26)/2 | O26: =N26*Assumptions!$B$18/12 | P26: =I26*Assumptions!$B$19 | Q26: =O26+P26 | R26: =Assumptions!$B$33*(1+Assumptions!$B$34)^(C26-1)/12 | S26: =L26 | T26: =Q26-R26-S26-AP26 | U26: =MIN(AE26,M26*Assumptions!$B$24/(1+Assumptions!$B$24)) | V26: =((U26+U25)/2)*Assumptions!$B$23/12 | W26: =T26-V26+AJ26 | X26: =X25+W26 | Y26: =MAX(M26-U26,0) | Z26: =R26*Assumptions!$B$25 | AA26: =Y26+Z26 | AB26: =MAX(AB25,AA26) | AC26: 0 | AD26: =AK26+AC26 | AE26: =IF(SUM($H$4:H26)<Assumptions!$B$57,0,MAX(MAX(Assumptions!$B$44,AE25),IF(M26*Assumptions!$B$24/(1+Assumptions!$B$24)>MAX(Assumptions!$B$44,AE25)*Assumptions!$B$53,M26*Assumptions!$B$24/(1+Assumptions!$B$24)/Assumptions!$B$54,MAX(Assumptions!$B$44,AE25)))) | AF26: =U26-U25 | AG26: =IFERROR(U26/AE26,0) | AH26: =MAX(0,AE26-AE25) | AI26: =MAX(AD25-Z26,0) | AJ26: =AI26*Assumptions!$B$46/12 | AK26: =AD25+Q26-R26-I26+K26+AF26-V26+AJ26-AP26 | AL26: =TRIM(IF(AH26>0,"Increase warehouse facility to $"&TEXT(AE26,"#,##0")&" (from $"&TEXT(AE25,"#,##0")&"). ","")&IF(AC26>0,"Raise ~$"&TEXT(AC26,"#,##0")&" of equity — annual raise, funds the next 12 months.","")) | AM26: =Q26-R26-I26+K26+AF26-V26-AP26 | AN26: =SUM($H$4:H26) | AO26: =H26*Assumptions!$B$16 | AP26: =MAX(AO26*Assumptions!$B$62,Assumptions!$B$63)+Assumptions!$B$64/12 | AQ26: =(O26+P26)*Assumptions!$B$61/(1-Assumptions!$B$61)
A27: 24 | B27: =EDATE(Assumptions!$B$4,23) | C27: =INT((A27-1)/12)+1 | D27: =IF(C27=1,Assumptions!$B$6,IF(C27=2,Assumptions!$B$7,IF(C27=3,Assumptions!$B$8,IF(C27=4,Assumptions!$B$9,Assumptions!$B$10)))) | E27: =ROUND(F26*Assumptions!$B$11,0) | F27: =F26+D27-E27 | G27: =ROUND(F27*Assumptions!$B$14*(365/12/7),0) | H27: =ROUND(G27*Assumptions!$B$15,0) | I27: =AO27*(1-Assumptions!$B$61) | J27: =M26 | K27: =IFERROR(J27/Assumptions!$B$17,0) | L27: =J27*Assumptions!$B$20/12 | M27: =MAX(J27+I27-K27-L27,0) | N27: =(J27+M27)/2 | O27: =N27*Assumptions!$B$18/12 | P27: =I27*Assumptions!$B$19 | Q27: =O27+P27 | R27: =Assumptions!$B$33*(1+Assumptions!$B$34)^(C27-1)/12 | S27: =L27 | T27: =Q27-R27-S27-AP27 | U27: =MIN(AE27,M27*Assumptions!$B$24/(1+Assumptions!$B$24)) | V27: =((U27+U26)/2)*Assumptions!$B$23/12 | W27: =T27-V27+AJ27 | X27: =X26+W27 | Y27: =MAX(M27-U27,0) | Z27: =R27*Assumptions!$B$25 | AA27: =Y27+Z27 | AB27: =MAX(AB26,AA27) | AC27: 0 | AD27: =AK27+AC27 | AE27: =IF(SUM($H$4:H27)<Assumptions!$B$57,0,MAX(MAX(Assumptions!$B$44,AE26),IF(M27*Assumptions!$B$24/(1+Assumptions!$B$24)>MAX(Assumptions!$B$44,AE26)*Assumptions!$B$53,M27*Assumptions!$B$24/(1+Assumptions!$B$24)/Assumptions!$B$54,MAX(Assumptions!$B$44,AE26)))) | AF27: =U27-U26 | AG27: =IFERROR(U27/AE27,0) | AH27: =MAX(0,AE27-AE26) | AI27: =MAX(AD26-Z27,0) | AJ27: =AI27*Assumptions!$B$46/12 | AK27: =AD26+Q27-R27-I27+K27+AF27-V27+AJ27-AP27 | AL27: =TRIM(IF(AH27>0,"Increase warehouse facility to $"&TEXT(AE27,"#,##0")&" (from $"&TEXT(AE26,"#,##0")&"). ","")&IF(AC27>0,"Raise ~$"&TEXT(AC27,"#,##0")&" of equity — annual raise, funds the next 12 months.","")) | AM27: =Q27-R27-I27+K27+AF27-V27-AP27 | AN27: =SUM($H$4:H27) | AO27: =H27*Assumptions!$B$16 | AP27: =MAX(AO27*Assumptions!$B$62,Assumptions!$B$63)+Assumptions!$B$64/12 | AQ27: =(O27+P27)*Assumptions!$B$61/(1-Assumptions!$B$61)
A28: 25 | B28: =EDATE(Assumptions!$B$4,24) | C28: =INT((A28-1)/12)+1 | D28: =IF(C28=1,Assumptions!$B$6,IF(C28=2,Assumptions!$B$7,IF(C28=3,Assumptions!$B$8,IF(C28=4,Assumptions!$B$9,Assumptions!$B$10)))) | E28: =ROUND(F27*Assumptions!$B$11,0) | F28: =F27+D28-E28 | G28: =ROUND(F28*Assumptions!$B$14*(365/12/7),0) | H28: =ROUND(G28*Assumptions!$B$15,0) | I28: =AO28*(1-Assumptions!$B$61) | J28: =M27 | K28: =IFERROR(J28/Assumptions!$B$17,0) | L28: =J28*Assumptions!$B$20/12 | M28: =MAX(J28+I28-K28-L28,0) | N28: =(J28+M28)/2 | O28: =N28*Assumptions!$B$18/12 | P28: =I28*Assumptions!$B$19 | Q28: =O28+P28 | R28: =Assumptions!$B$33*(1+Assumptions!$B$34)^(C28-1)/12 | S28: =L28 | T28: =Q28-R28-S28-AP28 | U28: =MIN(AE28,M28*Assumptions!$B$24/(1+Assumptions!$B$24)) | V28: =((U28+U27)/2)*Assumptions!$B$23/12 | W28: =T28-V28+AJ28 | X28: =X27+W28 | Y28: =MAX(M28-U28,0) | Z28: =R28*Assumptions!$B$25 | AA28: =Y28+Z28 | AB28: =MAX(AB27,AA28) | AC28: =MAX(0,MAX(Z28-AD27-AM28,Z29-AD27-SUM(AM28:AM29),Z30-AD27-SUM(AM28:AM30),Z31-AD27-SUM(AM28:AM31),Z32-AD27-SUM(AM28:AM32),Z33-AD27-SUM(AM28:AM33),Z34-AD27-SUM(AM28:AM34),Z35-AD27-SUM(AM28:AM35),Z36-AD27-SUM(AM28:AM36),Z37-AD27-SUM(AM28:AM37),Z38-AD27-SUM(AM28:AM38),Z39-AD27-SUM(AM28:AM39))) | AD28: =AK28+AC28 | AE28: =IF(SUM($H$4:H28)<Assumptions!$B$57,0,MAX(MAX(Assumptions!$B$44,AE27),IF(M28*Assumptions!$B$24/(1+Assumptions!$B$24)>MAX(Assumptions!$B$44,AE27)*Assumptions!$B$53,M28*Assumptions!$B$24/(1+Assumptions!$B$24)/Assumptions!$B$54,MAX(Assumptions!$B$44,AE27)))) | AF28: =U28-U27 | AG28: =IFERROR(U28/AE28,0) | AH28: =MAX(0,AE28-AE27) | AI28: =MAX(AD27-Z28,0) | AJ28: =AI28*Assumptions!$B$46/12 | AK28: =AD27+Q28-R28-I28+K28+AF28-V28+AJ28-AP28 | AL28: =TRIM(IF(AH28>0,"Increase warehouse facility to $"&TEXT(AE28,"#,##0")&" (from $"&TEXT(AE27,"#,##0")&"). ","")&IF(AC28>0,"Raise ~$"&TEXT(AC28,"#,##0")&" of equity — annual raise, funds the next 12 months.","")) | AM28: =Q28-R28-I28+K28+AF28-V28-AP28 | AN28: =SUM($H$4:H28) | AO28: =H28*Assumptions!$B$16 | AP28: =MAX(AO28*Assumptions!$B$62,Assumptions!$B$63)+Assumptions!$B$64/12 | AQ28: =(O28+P28)*Assumptions!$B$61/(1-Assumptions!$B$61)
A29: 26 | B29: =EDATE(Assumptions!$B$4,25) | C29: =INT((A29-1)/12)+1 | D29: =IF(C29=1,Assumptions!$B$6,IF(C29=2,Assumptions!$B$7,IF(C29=3,Assumptions!$B$8,IF(C29=4,Assumptions!$B$9,Assumptions!$B$10)))) | E29: =ROUND(F28*Assumptions!$B$11,0) | F29: =F28+D29-E29 | G29: =ROUND(F29*Assumptions!$B$14*(365/12/7),0) | H29: =ROUND(G29*Assumptions!$B$15,0) | I29: =AO29*(1-Assumptions!$B$61) | J29: =M28 | K29: =IFERROR(J29/Assumptions!$B$17,0) | L29: =J29*Assumptions!$B$20/12 | M29: =MAX(J29+I29-K29-L29,0) | N29: =(J29+M29)/2 | O29: =N29*Assumptions!$B$18/12 | P29: =I29*Assumptions!$B$19 | Q29: =O29+P29 | R29: =Assumptions!$B$33*(1+Assumptions!$B$34)^(C29-1)/12 | S29: =L29 | T29: =Q29-R29-S29-AP29 | U29: =MIN(AE29,M29*Assumptions!$B$24/(1+Assumptions!$B$24)) | V29: =((U29+U28)/2)*Assumptions!$B$23/12 | W29: =T29-V29+AJ29 | X29: =X28+W29 | Y29: =MAX(M29-U29,0) | Z29: =R29*Assumptions!$B$25 | AA29: =Y29+Z29 | AB29: =MAX(AB28,AA29) | AC29: 0 | AD29: =AK29+AC29 | AE29: =IF(SUM($H$4:H29)<Assumptions!$B$57,0,MAX(MAX(Assumptions!$B$44,AE28),IF(M29*Assumptions!$B$24/(1+Assumptions!$B$24)>MAX(Assumptions!$B$44,AE28)*Assumptions!$B$53,M29*Assumptions!$B$24/(1+Assumptions!$B$24)/Assumptions!$B$54,MAX(Assumptions!$B$44,AE28)))) | AF29: =U29-U28 | AG29: =IFERROR(U29/AE29,0) | AH29: =MAX(0,AE29-AE28) | AI29: =MAX(AD28-Z29,0) | AJ29: =AI29*Assumptions!$B$46/12 | AK29: =AD28+Q29-R29-I29+K29+AF29-V29+AJ29-AP29 | AL29: =TRIM(IF(AH29>0,"Increase warehouse facility to $"&TEXT(AE29,"#,##0")&" (from $"&TEXT(AE28,"#,##0")&"). ","")&IF(AC29>0,"Raise ~$"&TEXT(AC29,"#,##0")&" of equity — annual raise, funds the next 12 months.","")) | AM29: =Q29-R29-I29+K29+AF29-V29-AP29 | AN29: =SUM($H$4:H29) | AO29: =H29*Assumptions!$B$16 | AP29: =MAX(AO29*Assumptions!$B$62,Assumptions!$B$63)+Assumptions!$B$64/12 | AQ29: =(O29+P29)*Assumptions!$B$61/(1-Assumptions!$B$61)
A30: 27 | B30: =EDATE(Assumptions!$B$4,26) | C30: =INT((A30-1)/12)+1 | D30: =IF(C30=1,Assumptions!$B$6,IF(C30=2,Assumptions!$B$7,IF(C30=3,Assumptions!$B$8,IF(C30=4,Assumptions!$B$9,Assumptions!$B$10)))) | E30: =ROUND(F29*Assumptions!$B$11,0) | F30: =F29+D30-E30 | G30: =ROUND(F30*Assumptions!$B$14*(365/12/7),0) | H30: =ROUND(G30*Assumptions!$B$15,0) | I30: =AO30*(1-Assumptions!$B$61) | J30: =M29 | K30: =IFERROR(J30/Assumptions!$B$17,0) | L30: =J30*Assumptions!$B$20/12 | M30: =MAX(J30+I30-K30-L30,0) | N30: =(J30+M30)/2 | O30: =N30*Assumptions!$B$18/12 | P30: =I30*Assumptions!$B$19 | Q30: =O30+P30 | R30: =Assumptions!$B$33*(1+Assumptions!$B$34)^(C30-1)/12 | S30: =L30 | T30: =Q30-R30-S30-AP30 | U30: =MIN(AE30,M30*Assumptions!$B$24/(1+Assumptions!$B$24)) | V30: =((U30+U29)/2)*Assumptions!$B$23/12 | W30: =T30-V30+AJ30 | X30: =X29+W30 | Y30: =MAX(M30-U30,0) | Z30: =R30*Assumptions!$B$25 | AA30: =Y30+Z30 | AB30: =MAX(AB29,AA30) | AC30: 0 | AD30: =AK30+AC30 | AE30: =IF(SUM($H$4:H30)<Assumptions!$B$57,0,MAX(MAX(Assumptions!$B$44,AE29),IF(M30*Assumptions!$B$24/(1+Assumptions!$B$24)>MAX(Assumptions!$B$44,AE29)*Assumptions!$B$53,M30*Assumptions!$B$24/(1+Assumptions!$B$24)/Assumptions!$B$54,MAX(Assumptions!$B$44,AE29)))) | AF30: =U30-U29 | AG30: =IFERROR(U30/AE30,0) | AH30: =MAX(0,AE30-AE29) | AI30: =MAX(AD29-Z30,0) | AJ30: =AI30*Assumptions!$B$46/12 | AK30: =AD29+Q30-R30-I30+K30+AF30-V30+AJ30-AP30 | AL30: =TRIM(IF(AH30>0,"Increase warehouse facility to $"&TEXT(AE30,"#,##0")&" (from $"&TEXT(AE29,"#,##0")&"). ","")&IF(AC30>0,"Raise ~$"&TEXT(AC30,"#,##0")&" of equity — annual raise, funds the next 12 months.","")) | AM30: =Q30-R30-I30+K30+AF30-V30-AP30 | AN30: =SUM($H$4:H30) | AO30: =H30*Assumptions!$B$16 | AP30: =MAX(AO30*Assumptions!$B$62,Assumptions!$B$63)+Assumptions!$B$64/12 | AQ30: =(O30+P30)*Assumptions!$B$61/(1-Assumptions!$B$61)
A31: 28 | B31: =EDATE(Assumptions!$B$4,27) | C31: =INT((A31-1)/12)+1 | D31: =IF(C31=1,Assumptions!$B$6,IF(C31=2,Assumptions!$B$7,IF(C31=3,Assumptions!$B$8,IF(C31=4,Assumptions!$B$9,Assumptions!$B$10)))) | E31: =ROUND(F30*Assumptions!$B$11,0) | F31: =F30+D31-E31 | G31: =ROUND(F31*Assumptions!$B$14*(365/12/7),0) | H31: =ROUND(G31*Assumptions!$B$15,0) | I31: =AO31*(1-Assumptions!$B$61) | J31: =M30 | K31: =IFERROR(J31/Assumptions!$B$17,0) | L31: =J31*Assumptions!$B$20/12 | M31: =MAX(J31+I31-K31-L31,0) | N31: =(J31+M31)/2 | O31: =N31*Assumptions!$B$18/12 | P31: =I31*Assumptions!$B$19 | Q31: =O31+P31 | R31: =Assumptions!$B$33*(1+Assumptions!$B$34)^(C31-1)/12 | S31: =L31 | T31: =Q31-R31-S31-AP31 | U31: =MIN(AE31,M31*Assumptions!$B$24/(1+Assumptions!$B$24)) | V31: =((U31+U30)/2)*Assumptions!$B$23/12 | W31: =T31-V31+AJ31 | X31: =X30+W31 | Y31: =MAX(M31-U31,0) | Z31: =R31*Assumptions!$B$25 | AA31: =Y31+Z31 | AB31: =MAX(AB30,AA31) | AC31: 0 | AD31: =AK31+AC31 | AE31: =IF(SUM($H$4:H31)<Assumptions!$B$57,0,MAX(MAX(Assumptions!$B$44,AE30),IF(M31*Assumptions!$B$24/(1+Assumptions!$B$24)>MAX(Assumptions!$B$44,AE30)*Assumptions!$B$53,M31*Assumptions!$B$24/(1+Assumptions!$B$24)/Assumptions!$B$54,MAX(Assumptions!$B$44,AE30)))) | AF31: =U31-U30 | AG31: =IFERROR(U31/AE31,0) | AH31: =MAX(0,AE31-AE30) | AI31: =MAX(AD30-Z31,0) | AJ31: =AI31*Assumptions!$B$46/12 | AK31: =AD30+Q31-R31-I31+K31+AF31-V31+AJ31-AP31 | AL31: =TRIM(IF(AH31>0,"Increase warehouse facility to $"&TEXT(AE31,"#,##0")&" (from $"&TEXT(AE30,"#,##0")&"). ","")&IF(AC31>0,"Raise ~$"&TEXT(AC31,"#,##0")&" of equity — annual raise, funds the next 12 months.","")) | AM31: =Q31-R31-I31+K31+AF31-V31-AP31 | AN31: =SUM($H$4:H31) | AO31: =H31*Assumptions!$B$16 | AP31: =MAX(AO31*Assumptions!$B$62,Assumptions!$B$63)+Assumptions!$B$64/12 | AQ31: =(O31+P31)*Assumptions!$B$61/(1-Assumptions!$B$61)
A32: 29 | B32: =EDATE(Assumptions!$B$4,28) | C32: =INT((A32-1)/12)+1 | D32: =IF(C32=1,Assumptions!$B$6,IF(C32=2,Assumptions!$B$7,IF(C32=3,Assumptions!$B$8,IF(C32=4,Assumptions!$B$9,Assumptions!$B$10)))) | E32: =ROUND(F31*Assumptions!$B$11,0) | F32: =F31+D32-E32 | G32: =ROUND(F32*Assumptions!$B$14*(365/12/7),0) | H32: =ROUND(G32*Assumptions!$B$15,0) | I32: =AO32*(1-Assumptions!$B$61) | J32: =M31 | K32: =IFERROR(J32/Assumptions!$B$17,0) | L32: =J32*Assumptions!$B$20/12 | M32: =MAX(J32+I32-K32-L32,0) | N32: =(J32+M32)/2 | O32: =N32*Assumptions!$B$18/12 | P32: =I32*Assumptions!$B$19 | Q32: =O32+P32 | R32: =Assumptions!$B$33*(1+Assumptions!$B$34)^(C32-1)/12 | S32: =L32 | T32: =Q32-R32-S32-AP32 | U32: =MIN(AE32,M32*Assumptions!$B$24/(1+Assumptions!$B$24)) | V32: =((U32+U31)/2)*Assumptions!$B$23/12 | W32: =T32-V32+AJ32 | X32: =X31+W32 | Y32: =MAX(M32-U32,0) | Z32: =R32*Assumptions!$B$25 | AA32: =Y32+Z32 | AB32: =MAX(AB31,AA32) | AC32: 0 | AD32: =AK32+AC32 | AE32: =IF(SUM($H$4:H32)<Assumptions!$B$57,0,MAX(MAX(Assumptions!$B$44,AE31),IF(M32*Assumptions!$B$24/(1+Assumptions!$B$24)>MAX(Assumptions!$B$44,AE31)*Assumptions!$B$53,M32*Assumptions!$B$24/(1+Assumptions!$B$24)/Assumptions!$B$54,MAX(Assumptions!$B$44,AE31)))) | AF32: =U32-U31 | AG32: =IFERROR(U32/AE32,0) | AH32: =MAX(0,AE32-AE31) | AI32: =MAX(AD31-Z32,0) | AJ32: =AI32*Assumptions!$B$46/12 | AK32: =AD31+Q32-R32-I32+K32+AF32-V32+AJ32-AP32 | AL32: =TRIM(IF(AH32>0,"Increase warehouse facility to $"&TEXT(AE32,"#,##0")&" (from $"&TEXT(AE31,"#,##0")&"). ","")&IF(AC32>0,"Raise ~$"&TEXT(AC32,"#,##0")&" of equity — annual raise, funds the next 12 months.","")) | AM32: =Q32-R32-I32+K32+AF32-V32-AP32 | AN32: =SUM($H$4:H32) | AO32: =H32*Assumptions!$B$16 | AP32: =MAX(AO32*Assumptions!$B$62,Assumptions!$B$63)+Assumptions!$B$64/12 | AQ32: =(O32+P32)*Assumptions!$B$61/(1-Assumptions!$B$61)
